Workbook
Name Slicer_City: #N/A

Sheet Cafe_Sales_Data
A1: Bill_ID | B1: Customer_ID | C1: Order_Date | D1: City | E1: Item_Category | F1: Item_Name | G1: Quantity | H1: Discount | I1: Total_Sales | J1: Profit | K1: Payment_Mode | L1: Order_Type | M1: Customer Status | N1: Year | O1: Discount Check | R1: Average Bill Value | T1: NOTE
A2: CB0001 | B2: C400 | C2: 45422 | D2: Ahmedabad | E2: Desserts | F2: Cake | G2: 2 | H2: 0 | I2: 544 | J2: 108.8 | K2: Card | L2: Takeaway | M2: =IF(COUNTIF(B:B,B2)>1,"Repeat","New") -> Repeat | N2: =TEXT(C2,"yyyy") -> 2024 | O2: =IF(H2>=0.15,"High",IF(H2>=0.1,"Medium","Least or No")) -> Least or No | R2: =AVERAGE(I2:I351) -> 593.149 | T2: Conatins no duplicated values or empty values and fort as need number, date, currency
A3: CB0002 | B3: C177 | C3: 45579 | D3: Mumbai | E3: Snacks | F3: Fries | G3: 2 | H3: 0 | I3: 540 | J3: 162 | K3: UPI | L3: Dine-In | M3: =IF(COUNTIF(B:B,B3)>1,"Repeat","New") -> New | N3: =TEXT(C3,"yyyy") -> 2024 | O3: =IF(H3>=0.15,"High",IF(H3>=0.1,"Medium","Least or No")) -> Least or No
A4: CB0003 | B4: C607 | C4: 45986 | D4: Mumbai | E4: Snacks | F4: Burger | G4: 1 | H4: 0.15 | I4: 192.1 | J4: 57.63 | K4: Card | L4: Dine-In | M4: =IF(COUNTIF(B:B,B4)>1,"Repeat","New") -> Repeat | N4: =TEXT(C4,"yyyy") -> 2025 | O4: =IF(H4>=0.15,"High",IF(H4>=0.1,"Medium","Least or No")) -> High | R4: Repeat %
A5: CB0004 | B5: C672 | C5: 45269 | D5: Ahmedabad | E5: Beverages | F5: Tea | G5: 2 | H5: 0.1 | I5: 628.2 | J5: 157.05 | K5: Card | L5: Takeaway | M5: =IF(COUNTIF(B:B,B5)>1,"Repeat","New") -> Repeat | N5: =TEXT(C5,"yyyy") -> 2023 | O5: =IF(H5>=0.15,"High",IF(H5>=0.1,"Medium","Least or No")) -> Medium | R5: =COUNTIF(M2:M351,"Repeat") -> 298
A6: CB0005 | B6: C201 | C6: 44953 | D6: Rajkot | E6: Beverages | F6: Cold Coffee | G6: 3 | H6: 0.05 | I6: 658.35 | J6: 164.59 | K6: Cash | L6: Takeaway | M6: =IF(COUNTIF(B:B,B6)>1,"Repeat","New") -> New | N6: =TEXT(C6,"yyyy") -> 2023 | O6: =IF(H6>=0.15,"High",IF(H6>=0.1,"Medium","Least or No")) -> Least or No | R6: Total | T6: NOTE
A7: CB0006 | B7: C202 | C7: 45210 | D7: Mumbai | E7: Beverages | F7: Cold Coffee | G7: 1 | H7: 0.1 | I7: 262.8 | J7: 52.56 | K7: UPI | L7: Dine-In | M7: =IF(COUNTIF(B:B,B7)>1,"Repeat","New") -> New | N7: =TEXT(C7,"yyyy") -> 2023 | O7: =IF(H7>=0.15,"High",IF(H7>=0.1,"Medium","Least or No")) -> Medium | R7: =COUNTA(M2:M351) -> 350 | T7: If condition used to check repeate or new customer
A8: CB0007 | B8: C203 | C8: 45850 | D8: Surat | E8: Beverages | F8: Coffee | G8: 3 | H8: 0.15 | I8: 920.55 | J8: 230.14 | K8: UPI | L8: Dine-In | M8: =IF(COUNTIF(B:B,B8)>1,"Repeat","New") -> New | N8: =TEXT(C8,"yyyy") -> 2025 | O8: =IF(H8>=0.15,"High",IF(H8>=0.1,"Medium","Least or No")) -> High
A9: CB0008 | B9: C204 | C9: 45367 | D9: Ahmedabad | E9: Desserts | F9: Brownie | G9: 2 | H9: 0 | I9: 222 | J9: 66.6 | K9: Card | L9: Dine-In | M9: =IF(COUNTIF(B:B,B9)>1,"Repeat","New") -> Repeat | N9: =TEXT(C9,"yyyy") -> 2024 | O9: =IF(H9>=0.15,"High",IF(H9>=0.1,"Medium","Least or No")) -> Least or No | R9: =R5/R7*100 -> 85.142857
A10: CB0009 | B10: C914 | C10: 45157 | D10: Ahmedabad | E10: Snacks | F10: Puff | G10: 1 | H10: 0.05 | I10: 308.75 | J10: 77.19 | K10: Card | L10: Takeaway | M10: =IF(COUNTIF(B:B,B10)>1,"Repeat","New") -> Repeat | N10: =TEXT(C10,"yyyy") -> 2023 | O10: =IF(H10>=0.15,"High",IF(H10>=0.1,"Medium","Least or No")) -> Least or No
A11: CB0010 | B11: C376 | C11: 45460 | D11: Mumbai | E11: Beverages | F11: Tea | G11: 3 | H11: 0.1 | I11: 739.8 | J11: 147.96 | K11: UPI | L11: Takeaway | M11: =IF(COUNTIF(B:B,B11)>1,"Repeat","New") -> Repeat | N11: =TEXT(C11,"yyyy") -> 2024 | O11: =IF(H11>=0.15,"High",IF(H11>=0.1,"Medium","Least or No")) -> Medium | Q11: DATE & TIME FUNCTION | T11: NOTE
A12: CB0011 | B12: C371 | C12: 44990 | D12: Mumbai | E12: Beverages | F12: Tea | G12: 1 | H12: 0.05 | I12: 168.15 | J12: 50.45 | K12: Card | L12: Dine-In | M12: =IF(COUNTIF(B:B,B12)>1,"Repeat","New") -> Repeat | N12: =TEXT(C12,"yyyy") -> 2023 | O12: =IF(H12>=0.15,"High",IF(H12>=0.1,"Medium","Least or No")) -> Least or No | Q12: Today | R12: =TODAY() -> 46076 | T12: text tool used to extract just year from date
A13: CB0012 | B13: C414 | C13: 45265 | D13: Rajkot | E13: Beverages | F13: Tea | G13: 3 | H13: 0.15 | I13: 762.45 | J13: 228.73 | K13: UPI | L13: Dine-In | M13: =IF(COUNTIF(B:B,B13)>1,"Repeat","New") -> Repeat | N13: =TEXT(C13,"yyyy") -> 2023 | O13: =IF(H13>=0.15,"High",IF(H13>=0.1,"Medium","Least or No")) -> High | Q13: Now | R13: =NOW() -> 46076.822
A14: CB0013 | B14: C400 | C14: 45086 | D14: Rajkot | E14: Desserts | F14: Muffin | G14: 1 | H14: 0.1 | I14: 294.3 | J14: 88.29 | K14: UPI | L14: Dine-In | M14: =IF(COUNTIF(B:B,B14)>1,"Repeat","New") -> Repeat | N14: =TEXT(C14,"yyyy") -> 2023 | O14: =IF(H14>=0.15,"High",IF(H14>=0.1,"Medium","Least or No")) -> Medium
A15: CB0014 | B15: C401 | C15: 45268 | D15: Surat | E15: Snacks | F15: Fries | G15: 3 | H15: 0.05 | I15: 285 | J15: 71.25 | K15: Cash | L15: Dine-In | M15: =IF(COUNTIF(B:B,B15)>1,"Repeat","New") -> New | N15: =TEXT(C15,"yyyy") -> 2023 | O15: =IF(H15>=0.15,"High",IF(H15>=0.1,"Medium","Least or No")) -> Least or No
A16: CB0015 | B16: C402 | C16: 45184 | D16: Vadodara | E16: Desserts | F16: Muffin | G16: 4 | H16: 0 | I16: 956 | J16: 191.2 | K16: Card | L16: Dine-In | M16: =IF(COUNTIF(B:B,B16)>1,"Repeat","New") -> New | N16: =TEXT(C16,"yyyy") -> 2023 | O16: =IF(H16>=0.15,"High",IF(H16>=0.1,"Medium","Least or No")) -> Least or No | T16: NOTE
A17: CB0016 | B17: C403 | C17: 45298 | D17: Vadodara | E17: Beverages | F17: Cappuccino | G17: 3 | H17: 0 | I17: 786 | J17: 196.5 | K17: Card | L17: Takeaway | M17: =IF(COUNTIF(B:B,B17)>1,"Repeat","New") -> New | N17: =TEXT(C17,"yyyy") -> 2024 | O17: =IF(H17>=0.15,"High",IF(H17>=0.1,"Medium","Least or No")) -> Least or No | T17: Average found from sales hence bill values average
A18: CB0017 | B18: C519 | C18: 45127 | D18: Rajkot | E18: Beverages | F18: Cappuccino | G18: 1 | H18: 0.1 | I18: 284.4 | J18: 85.32 | K18: Card | L18: Dine-In | M18: =IF(COUNTIF(B:B,B18)>1,"Repeat","New") -> Repeat | N18: =TEXT(C18,"yyyy") -> 2023 | O18: =IF(H18>=0.15,"High",IF(H18>=0.1,"Medium","Least or No")) -> Medium
A19: CB0018 | B19: C846 | C19: 45870 | D19: Ahmedabad | E19: Beverages | F19: Latte | G19: 3 | H19: 0.1 | I19: 1026 | J19: 307.8 | K19: UPI | L19: Dine-In | M19: =IF(COUNTIF(B:B,B19)>1,"Repeat","New") -> Repeat | N19: =TEXT(C19,"yyyy") -> 2025 | O19: =IF(H19>=0.15,"High",IF(H19>=0.1,"Medium","Least or No")) -> Medium
A20: CB0019 | B20: C596 | C20: 45493 | D20: Surat | E20: Desserts | F20: Cake | G20: 1 | H20: 0.15 | I20: 170.85 | J20: 42.71 | K20: Card | L20: Dine-In | M20: =IF(COUNTIF(B:B,B20)>1,"Repeat","New") -> Repeat | N20: =TEXT(C20,"yyyy") -> 2024 | O20: =IF(H20>=0.15,"High",IF(H20>=0.1,"Medium","Least or No")) -> High
A21: CB0020 | B21: C350 | C21: 45462 | D21: Surat | E21: Snacks | F21: Burger | G21: 4 | H21: 0.15 | I21: 578 | J21: 173.4 | K21: Cash | L21: Takeaway | M21: =IF(COUNTIF(B:B,B21)>1,"Repeat","New") -> Repeat | N21: =TEXT(C21,"yyyy") -> 2024 | O21: =IF(H21>=0.15,"High",IF(H21>=0.1,"Medium","Least or No")) -> High | T21: NOTE
A22: CB0021 | B22: C287 | C22: 45908 | D22: Rajkot | E22: Desserts | F22: Ice Cream | G22: 3 | H22: 0.15 | I22: 362.1 | J22: 72.42 | K22: Cash | L22: Dine-In | M22: =IF(COUNTIF(B:B,B22)>1,"Repeat","New") -> Repeat | N22: =TEXT(C22,"yyyy") -> 2025 | O22: =IF(H22>=0.15,"High",IF(H22>=0.1,"Medium","Least or No")) -> High | T22: Count if and count a used to get percentage of repeat customers
A23: CB0022 | B23: C111 | C23: 45262 | D23: Vadodara | E23: Beverages | F23: Tea | G23: 1 | H23: 0 | I23: 433 | J23: 86.6 | K23: UPI | L23: Dine-In | M23: =IF(COUNTIF(B:B,B23)>1,"Repeat","New") -> New | N23: =TEXT(C23,"yyyy") -> 2023 | O23: =IF(H23>=0.15,"High",IF(H23>=0.1,"Medium","Least or No")) -> Least or No
A24: CB0023 | B24: C100 | C24: 45593 | D24: Surat | E24: Beverages | F24: Cold Coffee | G24: 2 | H24: 0.1 | I24: 651.6 | J24: 162.9 | K24: Cash | L24: Takeaway | M24: =IF(COUNTIF(B:B,B24)>1,"Repeat","New") -> New | N24: =TEXT(C24,"yyyy") -> 2024 | O24: =IF(H24>=0.15,"High",IF(H24>=0.1,"Medium","Least or No")) -> Medium
A25: CB0024 | B25: C300 | C25: 45942 | D25: Mumbai | E25: Snacks | F25: Fries | G25: 2 | H25: 0 | I25: 478 | J25: 95.6 | K25: UPI | L25: Takeaway | M25: =IF(COUNTIF(B:B,B25)>1,"Repeat","New") -> New | N25: =TEXT(C25,"yyyy") -> 2025 | O25: =IF(H25>=0.15,"High",IF(H25>=0.1,"Medium","Least or No")) -> Least or No
A26: CB0025 | B26: C147 | C26: 45062 | D26: Vadodara | E26: Desserts | F26: Ice Cream | G26: 4 | H26: 0.1 | I26: 1191.6 | J26: 297.9 | K26: Cash | L26: Dine-In | M26: =IF(COUNTIF(B:B,B26)>1,"Repeat","New") -> Repeat | N26: =TEXT(C26,"yyyy") -> 2023 | O26: =IF(H26>=0.15,"High",IF(H26>=0.1,"Medium","Least or No")) -> Medium | T26: NOTE
A27: CB0026 | B27: C540 | C27: 45356 | D27: Rajkot | E27: Desserts | F27: Muffin | G27: 1 | H27: 0.15 | I27: 133.45 | J27: 26.69 | K27: Card | L27: Takeaway | M27: =IF(COUNTIF(B:B,B27)>1,"Repeat","New") -> Repeat | N27: =TEXT(C27,"yyyy") -> 2024 | O27: =IF(H27>=0.15,"High",IF(H27>=0.1,"Medium","Least or No")) -> High | T27: Nested if used to check conditions for discount check
A28: CB0027 | B28: C204 | C28: 45573 | D28: Rajkot | E28: Desserts | F28: Brownie | G28: 2 | H28: 0.05 | I28: 532 | J28: 159.6 | K28: Cash | L28: Takeaway | M28: =IF(COUNTIF(B:B,B28)>1,"Repeat","New") -> Repeat | N28: =TEXT(C28,"yyyy") -> 2024 | O28: =IF(H28>=0.15,"High",IF(H28>=0.1,"Medium","Least or No")) -> Least or No
A29: CB0028 | B29: C483 | C29: 44965 | D29: Ahmedabad | E29: Desserts | F29: Cake | G29: 1 | H29: 0.15 | I29: 88.4 | J29: 26.52 | K29: Cash | L29: Dine-In | M29: =IF(COUNTIF(B:B,B29)>1,"Repeat","New") -> Repeat | N29: =TEXT(C29,"yyyy") -> 2023 | O29: =IF(H29>=0.15,"High",IF(H29>=0.1,"Medium","Least or No")) -> High
A30: CB0029 | B30: C523 | C30: 45322 | D30: Rajkot | E30: Snacks | F30: Burger | G30: 4 | H30: 0.15 | I30: 945.2 | J30: 189.04 | K30: UPI | L30: Takeaway | M30: =IF(COUNTIF(B:B,B30)>1,"Repeat","New") -> Repeat | N30: =TEXT(C30,"yyyy") -> 2024 | O30: =IF(H30>=0.15,"High",IF(H30>=0.1,"Medium","Least or No")) -> High
A31: CB0030 | B31: C739 | C31: 45243 | D31: Surat | E31: Snacks | F31: Fries | G31: 4 | H31: 0.15 | I31: 499.8 | J31: 124.95 | K31: Cash | L31: Takeaway | M31: =IF(COUNTIF(B:B,B31)>1,"Repeat","New") -> Repeat | N31: =TEXT(C31,"yyyy") -> 2023 | O31: =IF(H31>=0.15,"High",IF(H31>=0.1,"Medium","Least or No")) -> High
A32: CB0031 | B32: C432 | C32: 45022 | D32: Vadodara | E32: Beverages | F32: Cappuccino | G32: 3 | H32: 0.15 | I32: 841.5 | J32: 210.38 | K32: Card | L32: Takeaway | M32: =IF(COUNTIF(B:B,B32)>1,"Repeat","New") -> Repeat | N32: =TEXT(C32,"yyyy") -> 2023 | O32: =IF(H32>=0.15,"High",IF(H32>=0.1,"Medium","Least or No")) -> High
A33: CB0032 | B33: C735 | C33: 45142 | D33: Ahmedabad | E33: Desserts | F33: Muffin | G33: 2 | H33: 0.15 | I33: 564.4 | J33: 141.1 | K33: Card | L33: Takeaway | M33: =IF(COUNTIF(B:B,B33)>1,"Repeat","New") -> New | N33: =TEXT(C33,"yyyy") -> 2023 | O33: =IF(H33>=0.15,"High",IF(H33>=0.1,"Medium","Least or No")) -> High
A34: CB0033 | B34: C285 | C34: 45210 | D34: Surat | E34: Desserts | F34: Muffin | G34: 1 | H34: 0 | I34: 250 | J34: 75 | K34: Card | L34: Takeaway | M34: =IF(COUNTIF(B:B,B34)>1,"Repeat","New") -> Repeat | N34: =TEXT(C34,"yyyy") -> 2023 | O34: =IF(H34>=0.15,"High",IF(H34>=0.1,"Medium","Least or No")) -> Least or No
A35: CB0034 | B35: C318 | C35: 45266 | D35: Mumbai | E35: Beverages | F35: Cold Coffee | G35: 3 | H35: 0.15 | I35: 846.6 | J35: 169.32 | K35: UPI | L35: Takeaway | M35: =IF(COUNTIF(B:B,B35)>1,"Repeat","New") -> New | N35: =TEXT(C35,"yyyy") -> 2023 | O35: =IF(H35>=0.15,"High",IF(H35>=0.1,"Medium","Least or No")) -> High
A36: CB0035 | B36: C674 | C36: 45741 | D36: Rajkot | E36: Desserts | F36: Brownie | G36: 2 | H36: 0.1 | I36: 590.4 | J36: 177.12 | K36: Card | L36: Dine-In | M36: =IF(COUNTIF(B:B,B36)>1,"Repeat","New") -> Repeat | N36: =TEXT(C36,"yyyy") -> 2025 | O36: =IF(H36>=0.15,"High",IF(H36>=0.1,"Medium","Least or No")) -> Medium
A37: CB0036 | B37: C657 | C37: 45711 | D37: Rajkot | E37: Snacks | F37: Sandwich | G37: 1 | H37: 0 | I37: 231 | J37: 57.75 | K37: UPI | L37: Dine-In | M37: =IF(COUNTIF(B:B,B37)>1,"Repeat","New") -> Repeat | N37: =TEXT(C37,"yyyy") -> 2025 | O37: =IF(H37>=0.15,"High",IF(H37>=0.1,"Medium","Least or No")) -> Least or No
A38: CB0037 | B38: C607 | C38: 45794 | D38: Surat | E38: Desserts | F38: Brownie | G38: 3 | H38: 0.15 | I38: 726.75 | J38: 145.35 | K38: Cash | L38: Takeaway | M38: =IF(COUNTIF(B:B,B38)>1,"Repeat","New") -> Repeat | N38: =TEXT(C38,"yyyy") -> 2025 | O38: =IF(H38>=0.15,"High",IF(H38>=0.1,"Medium","Least or No")) -> High
A39: CB0038 | B39: C205 | C39: 45369 | D39: Rajkot | E39: Beverages | F39: Cold Coffee | G39: 3 | H39: 0.05 | I39: 515.85 | J39: 103.17 | K39: Card | L39: Takeaway | M39: =IF(COUNTIF(B:B,B39)>1,"Repeat","New") -> Repeat | N39: =TEXT(C39,"yyyy") -> 2024 | O39: =IF(H39>=0.15,"High",IF(H39>=0.1,"Medium","Least or No")) -> Least or No
... A351: CB0350 | B351: C489 | C351: 45761 | D351: Vadodara | E351: Beverages | F351: Cappuccino | G351: 2 | H351: 0.05 | I351: 283.1 | J351: 56.62 | K351: Cash | L351: Dine-In | M351: =IF(COUNTIF(B:B,B351)>1,"Repeat","New") -> Repeat | N351: =TEXT(C351,"yyyy") -> 2025 | O351: =IF(H351>=0.15,"High",IF(H351>=0.1,"Medium","Least or No")) -> Least or No

Sheet Sheet1
A1: Bill_ID | B1: Customer_ID | C1: Order_Date | D1: City | E1: Item_Category | F1: Item_Name | G1: Quantity | H1: Unit_Price | I1: Discount | J1: Total_Sales | K1: Profit | L1: Payment_Mode | M1: Order_Type | O1: ID | P1: Repeating Times | Q1: Sales | S1: Enter ID Below | T1: Sales | V1: NOTE
A2: CB0001 | B2: C400 | C2: 45422 | D2: Ahmedabad | E2: Desserts | F2: Cake | G2: 2 | H2: 272 | I2: 0 | J2: 544 | K2: 108.8 | L2: Card | M2: Takeaway | O2: {=_xlfn.UNIQUE(B2:B351)} -> C400 | P2: =COUNTIF($B$2:$B$351,O2) -> 2 | Q2: =SUMIF($B$2:$B$351,O2,$J$2:$J$351) -> 838.3 | S2: C201 | T2: =VLOOKUP($S$2,$B$2:$J$351,9,FALSE) -> 658.35 | V2: vlookup used enter the id and know sales
A3: CB0002 | B3: C177 | C3: 45579 | D3: Mumbai | E3: Snacks | F3: Fries | G3: 2 | H3: 270 | I3: 0 | J3: 540 | K3: 162 | L3: UPI | M3: Dine-In | O3: C177 | P3: =COUNTIF($B$2:$B$351,O3) -> 1 | Q3: =SUMIF($B$2:$B$351,O3,$J$2:$J$351) -> 540
A4: CB0003 | B4: C607 | C4: 45986 | D4: Mumbai | E4: Snacks | F4: Burger | G4: 1 | H4: 226 | I4: 0.15 | J4: 192.1 | K4: 57.63 | L4: Card | M4: Dine-In | O4: C607 | P4: =COUNTIF($B$2:$B$351,O4) -> 4 | Q4: =SUMIF($B$2:$B$351,O4,$J$2:$J$351) -> 2217.85
A5: CB0004 | B5: C672 | C5: 45269 | D5: Ahmedabad | E5: Beverages | F5: Tea | G5: 2 | H5: 349 | I5: 0.1 | J5: 628.2 | K5: 157.05 | L5: Card | M5: Takeaway | O5: C672 | P5: =COUNTIF($B$2:$B$351,O5) -> 4 | Q5: =SUMIF($B$2:$B$351,O5,$J$2:$J$351) -> 2656 | S5: High Value Customers
A6: CB0005 | B6: C201 | C6: 44953 | D6: Rajkot | E6: Beverages | F6: Cold Coffee | G6: 3 | H6: 231 | I6: 0.05 | J6: 658.35 | K6: 164.59 | L6: Cash | M6: Takeaway | O6: C201 | P6: =COUNTIF($B$2:$B$351,O6) -> 1 | Q6: =SUMIF($B$2:$B$351,O6,$J$2:$J$351) -> 658.35 | S6: {=_xlfn._xlws.FILTER(O2:O100,(P2:P100>5)*(Q2:Q100>2000))} -> C204 | V6: NOTE
A7: CB0006 | B7: C202 | C7: 45210 | D7: Mumbai | E7: Beverages | F7: Cold Coffee | G7: 1 | H7: 292 | I7: 0.1 | J7: 262.8 | K7: 52.56 | L7: UPI | M7: Dine-In | O7: C202 | P7: =COUNTIF($B$2:$B$351,O7) -> 1 | Q7: =SUMIF($B$2:$B$351,O7,$J$2:$J$351) -> 262.8 | S7: C846 | V7: Found high value customers with helper colums
A8: CB0007 | B8: C203 | C8: 45850 | D8: Surat | E8: Beverages | F8: Coffee | G8: 3 | H8: 361 | I8: 0.15 | J8: 920.55 | K8: 230.14 | L8: UPI | M8: Dine-In | O8: C203 | P8: =COUNTIF($B$2:$B$351,O8) -> 1 | Q8: =SUMIF($B$2:$B$351,O8,$J$2:$J$351) -> 920.55 | S8: C147
A9: CB0008 | B9: C204 | C9: 45367 | D9: Ahmedabad | E9: Desserts | F9: Brownie | G9: 2 | H9: 111 | I9: 0 | J9: 222 | K9: 66.6 | L9: Card | M9: Dine-In | O9: C204 | P9: =COUNTIF($B$2:$B$351,O9) -> 6 | Q9: =SUMIF($B$2:$B$351,O9,$J$2:$J$351) -> 3697 | S9: C674
A10: CB0009 | B10: C914 | C10: 45157 | D10: Ahmedabad | E10: Snacks | F10: Puff | G10: 1 | H10: 325 | I10: 0.05 | J10: 308.75 | K10: 77.19 | L10: Card | M10: Takeaway | O10: C914 | P10: =COUNTIF($B$2:$B$351,O10) -> 4 | Q10: =SUMIF($B$2:$B$351,O10,$J$2:$J$351) -> 2068.95 | S10: C169
A11: CB0010 | B11: C376 | C11: 45460 | D11: Mumbai | E11: Beverages | F11: Tea | G11: 3 | H11: 274 | I11: 0.1 | J11: 739.8 | K11: 147.96 | L11: UPI | M11: Takeaway | O11: C376 | P11: =COUNTIF($B$2:$B$351,O11) -> 2 | Q11: =SUMIF($B$2:$B$351,O11,$J$2:$J$351) -> 824.8 | S11: C408
A12: CB0011 | B12: C371 | C12: 44990 | D12: Mumbai | E12: Beverages | F12: Tea | G12: 1 | H12: 177 | I12: 0.05 | J12: 168.15 | K12: 50.45 | L12: Card | M12: Dine-In | O12: C371 | P12: =COUNTIF($B$2:$B$351,O12) -> 2 | Q12: =SUMIF($B$2:$B$351,O12,$J$2:$J$351) -> 791.85 | S12: C734
A13: CB0012 | B13: C414 | C13: 45265 | D13: Rajkot | E13: Beverages | F13: Tea | G13: 3 | H13: 299 | I13: 0.15 | J13: 762.45 | K13: 228.73 | L13: UPI | M13: Dine-In | O13: C414 | P13: =COUNTIF($B$2:$B$351,O13) -> 4 | Q13: =SUMIF($B$2:$B$351,O13,$J$2:$J$351) -> 3220.1 | S13: C763
A14: CB0013 | B14: C400 | C14: 45086 | D14: Rajkot | E14: Desserts | F14: Muffin | G14: 1 | H14: 327 | I14: 0.1 | J14: 294.3 | K14: 88.29 | L14: UPI | M14: Dine-In | O14: C401 | P14: =COUNTIF($B$2:$B$351,O14) -> 1 | Q14: =SUMIF($B$2:$B$351,O14,$J$2:$J$351) -> 285 | S14: C555
A15: CB0014 | B15: C401 | C15: 45268 | D15: Surat | E15: Snacks | F15: Fries | G15: 3 | H15: 100 | I15: 0.05 | J15: 285 | K15: 71.25 | L15: Cash | M15: Dine-In | O15: C402 | P15: =COUNTIF($B$2:$B$351,O15) -> 1 | Q15: =SUMIF($B$2:$B$351,O15,$J$2:$J$351) -> 956
A16: CB0015 | B16: C402 | C16: 45184 | D16: Vadodara | E16: Desserts | F16: Muffin | G16: 4 | H16: 239 | I16: 0 | J16: 956 | K16: 191.2 | L16: Card | M16: Dine-In | O16: C403 | P16: =COUNTIF($B$2:$B$351,O16) -> 1 | Q16: =SUMIF($B$2:$B$351,O16,$J$2:$J$351) -> 786
A17: CB0016 | B17: C403 | C17: 45298 | D17: Vadodara | E17: Beverages | F17: Cappuccino | G17: 3 | H17: 262 | I17: 0 | J17: 786 | K17: 196.5 | L17: Card | M17: Takeaway | O17: C519 | P17: =COUNTIF($B$2:$B$351,O17) -> 4 | Q17: =SUMIF($B$2:$B$351,O17,$J$2:$J$351) -> 1124.85
A18: CB0017 | B18: C519 | C18: 45127 | D18: Rajkot | E18: Beverages | F18: Cappuccino | G18: 1 | H18: 316 | I18: 0.1 | J18: 284.4 | K18: 85.32 | L18: Card | M18: Dine-In | O18: C846 | P18: =COUNTIF($B$2:$B$351,O18) -> 6 | Q18: =SUMIF($B$2:$B$351,O18,$J$2:$J$351) -> 4588.75
A19: CB0018 | B19: C846 | C19: 45870 | D19: Ahmedabad | E19: Beverages | F19: Latte | G19: 3 | H19: 380 | I19: 0.1 | J19: 1026 | K19: 307.8 | L19: UPI | M19: Dine-In | O19: C596 | P19: =COUNTIF($B$2:$B$351,O19) -> 3 | Q19: =SUMIF($B$2:$B$351,O19,$J$2:$J$351) -> 800.05
A20: CB0019 | B20: C596 | C20: 45493 | D20: Surat | E20: Desserts | F20: Cake | G20: 1 | H20: 201 | I20: 0.15 | J20: 170.85 | K20: 42.71 | L20: Card | M20: Dine-In | O20: C350 | P20: =COUNTIF($B$2:$B$351,O20) -> 3 | Q20: =SUMIF($B$2:$B$351,O20,$J$2:$J$351) -> 1110
A21: CB0020 | B21: C350 | C21: 45462 | D21: Surat | E21: Snacks | F21: Burger | G21: 4 | H21: 170 | I21: 0.15 | J21: 578 | K21: 173.4 | L21: Cash | M21: Takeaway | O21: C287 | P21: =COUNTIF($B$2:$B$351,O21) -> 2 | Q21: =SUMIF($B$2:$B$351,O21,$J$2:$J$351) -> 1130.5
A22: CB0021 | B22: C287 | C22: 45908 | D22: Rajkot | E22: Desserts | F22: Ice Cream | G22: 3 | H22: 142 | I22: 0.15 | J22: 362.1 | K22: 72.42 | L22: Cash | M22: Dine-In | O22: C111 | P22: =COUNTIF($B$2:$B$351,O22) -> 1 | Q22: =SUMIF($B$2:$B$351,O22,$J$2:$J$351) -> 433
A23: CB0022 | B23: C111 | C23: 45262 | D23: Vadodara | E23: Beverages | F23: Tea | G23: 1 | H23: 433 | I23: 0 | J23: 433 | K23: 86.6 | L23: UPI | M23: Dine-In | O23: C100 | P23: =COUNTIF($B$2:$B$351,O23) -> 1 | Q23: =SUMIF($B$2:$B$351,O23,$J$2:$J$351) -> 651.6
A24: CB0023 | B24: C100 | C24: 45593 | D24: Surat | E24: Beverages | F24: Cold Coffee | G24: 2 | H24: 362 | I24: 0.1 | J24: 651.6 | K24: 162.9 | L24: Cash | M24: Takeaway | O24: C300 | P24: =COUNTIF($B$2:$B$351,O24) -> 1 | Q24: =SUMIF($B$2:$B$351,O24,$J$2:$J$351) -> 478
A25: CB0024 | B25: C300 | C25: 45942 | D25: Mumbai | E25: Snacks | F25: Fries | G25: 2 | H25: 239 | I25: 0 | J25: 478 | K25: 95.6 | L25: UPI | M25: Takeaway | O25: C147 | P25: =COUNTIF($B$2:$B$351,O25) -> 7 | Q25: =SUMIF($B$2:$B$351,O25,$J$2:$J$351) -> 3680.45
A26: CB0025 | B26: C147 | C26: 45062 | D26: Vadodara | E26: Desserts | F26: Ice Cream | G26: 4 | H26: 331 | I26: 0.1 | J26: 1191.6 | K26: 297.9 | L26: Cash | M26: Dine-In | O26: C540 | P26: =COUNTIF($B$2:$B$351,O26) -> 2 | Q26: =SUMIF($B$2:$B$351,O26,$J$2:$J$351) -> 587.55
... A143: CB0142 | B143: C273 | C143: 45977 | D143: Rajkot | E143: Snacks | F143: Fries | G143: 1 | H143: 264 | I143: 0.1 | J143: 237.6 | K143: 47.52 | L143: UPI | M143: Takeaway | O143: C713 | P143: =COUNTIF($B$2:$B$351,O143) -> 1 | Q143: =SUMIF($B$2:$B$351,O143,$J$2:$J$351) -> 848
A144: CB0143 | B144: C934 | C144: 46021 | D144: Mumbai | E144: Beverages | F144: Coffee | G144: 4 | H144: 433 | I144: 0 | J144: 1732 | K144: 519.6 | L144: Cash | M144: Dine-In
A145: CB0144 | B145: C846 | C145: 45050 | D145: Vadodara | E145: Beverages | F145: Cappuccino | G145: 3 | H145: 436 | I145: 0.05 | J145: 1242.6 | K145: 372.78 | L145: Card | M145: Dine-In
A146: CB0145 | B146: C766 | C146: 44981 | D146: Mumbai | E146: Snacks | F146: Fries | G146: 2 | H146: 124 | I146: 0 | J146: 248 | K146: 49.6 | L146: Card | M146: Takeaway | O146: Statistical Summary | T146: NOTE
A147: CB0146 | B147: C669 | C147: 45700 | D147: Vadodara | E147: Beverages | F147: Cold Coffee | G147: 3 | H147: 81 | I147: 0.15 | J147: 206.55 | K147: 41.31 | L147: Card | M147: Dine-In | O147: Column1 | Q147: Column2 | T147: used for numberd colums only giver overview of statistical data
A148: CB0147 | B148: C490 | C148: 45903 | D148: Rajkot | E148: Snacks | F148: Fries | G148: 4 | H148: 366 | I148: 0.1 | J148: 1317.6 | K148: 329.4 | L148: UPI | M148: Takeaway
A149: CB0148 | B149: C914 | C149: 45524 | D149: Rajkot | E149: Beverages | F149: Coffee | G149: 1 | H149: 209 | I149: 0 | J149: 209 | K149: 52.25 | L149: Card | M149: Takeaway | O149: Mean | P149: 593.149 | Q149: Mean | R149: 147.42683
A150: CB0149 | B150: C825 | C150: 45917 | D150: Mumbai | E150: Desserts | F150: Brownie | G150: 3 | H150: 357 | I150: 0.1 | J150: 963.9 | K150: 240.97 | L150: Card | M150: Dine-In | O150: Standard Error | P150: 19.585674 | Q150: Standard Error | R150: 5.0947013
A151: CB0150 | B151: C452 | C151: 45226 | D151: Mumbai | E151: Beverages | F151: Cold Coffee | G151: 2 | H151: 262 | I151: 0.15 | J151: 445.4 | K151: 89.08 | L151: Cash | M151: Takeaway | O151: Median | P151: 515.925 | Q151: Median | R151: 124.8
A152: CB0151 | B152: C669 | C152: 45833 | D152: Rajkot | E152: Desserts | F152: Muffin | G152: 4 | H152: 221 | I152: 0.15 | J152: 751.4 | K152: 225.42 | L152: UPI | M152: Takeaway | O152: Mode | P152: 684 | Q152: Mode | R152: 205.2
A153: CB0152 | B153: C361 | C153: 45229 | D153: Surat | E153: Snacks | F153: Puff | G153: 2 | H153: 352 | I153: 0.05 | J153: 668.8 | K153: 167.2 | L153: UPI | M153: Takeaway | O153: Standard Deviation | P153: 366.41441 | Q153: Standard Deviation | R153: 95.313134
A154: CB0153 | B154: C661 | C154: 45173 | D154: Ahmedabad | E154: Beverages | F154: Coffee | G154: 2 | H154: 434 | I154: 0 | J154: 868 | K154: 260.4 | L154: Cash | M154: Dine-In | O154: Sample Variance | P154: 134259.52 | Q154: Sample Variance | R154: 9084.5936
A155: CB0154 | B155: C479 | C155: 45506 | D155: Surat | E155: Beverages | F155: Cappuccino | G155: 3 | H155: 152 | I155: 0.05 | J155: 433.2 | K155: 86.64 | L155: Cash | M155: Takeaway | O155: Kurtosis | P155: 0.31010259 | Q155: Kurtosis | R155: 1.5511909
A156: CB0155 | B156: C169 | C156: 45698 | D156: Mumbai | E156: Beverages | F156: Coffee | G156: 3 | H156: 389 | I156: 0.15 | J156: 991.95 | K156: 198.39 | L156: Card | M156: Dine-In | O156: Skewness | P156: 0.87787307 | Q156: Skewness | R156: 1.1796801
...

Sheet Pivot
A1: Count of Customer Status | B1: Column Labels
A2: Row Labels | B2: Ahmedabad | C2: Mumbai | D2: Rajkot | E2: Surat | F2: Vadodara | G2: Grand Total | R2: NOTE
A3: New | B3: 6 | C3: 13 | D3: 16 | E3: 10 | F3: 7 | G3: 52 | R3: Created pivot tables and slicers added in dashbord directly
A4: Repeat | B4: 52 | C4: 60 | D4: 58 | E4: 63 | F4: 65 | G4: 298
A5: Grand Total | B5: 58 | C5: 73 | D5: 74 | E5: 73 | F5: 72 | G5: 350
A19: Row Labels | B19: Sum of Total_Sales
A20: Ahmedabad | B20: 32322.55
A21: Mumbai | B21: 47074.25
A22: Rajkot | B22: 41665.15
A23: Surat | B23: 41277.1
A24: Vadodara | B24: 45263.1
A25: Grand Total | B25: 207602.15
A34: Count of Order_Type | B34: Column Labels
A35: Row Labels | B35: Beverages | C35: Desserts | D35: Snacks | E35: Grand Total
A36: Ahmedabad | B36: 12 | C36: 21 | D36: 25 | E36: 58
A37: Mumbai | B37: 30 | C37: 21 | D37: 22 | E37: 73
A38: Rajkot | B38: 25 | C38: 19 | D38: 30 | E38: 74
A39: Surat | B39: 24 | C39: 30 | D39: 19 | E39: 73
A40: Vadodara | B40: 33 | C40: 19 | D40: 20 | E40: 72
A41: Grand Total | B41: 124 | C41: 110 | D41: 116 | E41: 350
A50: Row Labels | B50: Sum of Total_Sales
A51: 2023 | B51: 79365.9
A52: 2024 | B52: 64252.65
A53: 2025 | B53: 63983.6
A54: Grand Total | B54: 207602.15
A66: Row Labels | B66: Sum of Profit
A67: Beverages | B67: 19294.03
A68: Desserts | B68: 15382.07
A69: Snacks | B69: 16923.29
A70: Grand Total | B70: 51599.39

Sheet Dashboard
A1: Average Bill Value | E1: % Repeat | H1: DASHBOARD | N1: Profit Share
N2: Beverages | P2: =GETPIVOTDATA("Profit",Pivot!$A$66,"Item_Category","Beverages") -> 19294.03
A3: =Cafe_Sales_Data!R2 -> 593.149 | E3: =Cafe_Sales_Data!R9 -> 85.142857 | N3: Desserts | P3: =GETPIVOTDATA("Profit",Pivot!$A$66,"Item_Category","Desserts") -> 15382.07
N4: Snacks | P4: =GETPIVOTDATA("Profit",Pivot!$A$66,"Item_Category","Snacks") -> 16923.29
